[2024-12-13T00:58:27.983+0000] {local_task_job_runner.py:123} INFO - ::group::Pre task execution logs
[2024-12-13T00:58:27.999+0000] {taskinstance.py:2613} INFO - Dependencies all met for dep_context=non-requeueable deps ti=<TaskInstance: ecobalyse_dag.Load_Data manual__2024-12-13T00:57:15.184756+00:00 [queued]>
[2024-12-13T00:58:28.008+0000] {taskinstance.py:2613} INFO - Dependencies all met for dep_context=requeueable deps ti=<TaskInstance: ecobalyse_dag.Load_Data manual__2024-12-13T00:57:15.184756+00:00 [queued]>
[2024-12-13T00:58:28.008+0000] {taskinstance.py:2866} INFO - Starting attempt 2 of 3
[2024-12-13T00:58:28.021+0000] {taskinstance.py:2889} INFO - Executing <Task(PythonOperator): Load_Data> on 2024-12-13 00:57:15.184756+00:00
[2024-12-13T00:58:28.029+0000] {warnings.py:112} WARNING - /home/***/.local/lib/python3.12/site-packages/***/task/task_runner/standard_task_runner.py:70: DeprecationWarning: This process (pid=1733) is multi-threaded, use of fork() may lead to deadlocks in the child.
  pid = os.fork()

[2024-12-13T00:58:28.030+0000] {standard_task_runner.py:72} INFO - Started process 1735 to run task
[2024-12-13T00:58:28.032+0000] {standard_task_runner.py:104} INFO - Running: ['***', 'tasks', 'run', 'ecobalyse_dag', 'Load_Data', 'manual__2024-12-13T00:57:15.184756+00:00', '--job-id', '271', '--raw', '--subdir', 'DAGS_FOLDER/data_transformations.py', '--cfg-path', '/tmp/tmp9tyxl2jj']
[2024-12-13T00:58:28.033+0000] {standard_task_runner.py:105} INFO - Job 271: Subtask Load_Data
[2024-12-13T00:58:28.085+0000] {task_command.py:467} INFO - Running <TaskInstance: ecobalyse_dag.Load_Data manual__2024-12-13T00:57:15.184756+00:00 [running]> on host c8c82134bf48
[2024-12-13T00:58:28.355+0000] {taskinstance.py:3132} INFO - Exporting env vars: AIRFLOW_CTX_DAG_EMAIL='thiernosidybah232@gmail.com' AIRFLOW_CTX_DAG_OWNER='***' AIRFLOW_CTX_DAG_ID='ecobalyse_dag' AIRFLOW_CTX_TASK_ID='Load_Data' AIRFLOW_CTX_EXECUTION_DATE='2024-12-13T00:57:15.184756+00:00' AIRFLOW_CTX_TRY_NUMBER='2' AIRFLOW_CTX_DAG_RUN_ID='manual__2024-12-13T00:57:15.184756+00:00'
[2024-12-13T00:58:28.355+0000] {logging_mixin.py:190} INFO - Task instance is in running state
[2024-12-13T00:58:28.355+0000] {logging_mixin.py:190} INFO -  Previous state of the Task instance: queued
[2024-12-13T00:58:28.355+0000] {logging_mixin.py:190} INFO - Current task name:Load_Data state:running start_date:2024-12-13 00:58:27.999779+00:00
[2024-12-13T00:58:28.356+0000] {logging_mixin.py:190} INFO - Dag name:ecobalyse_dag and current dag run status:running
[2024-12-13T00:58:28.356+0000] {taskinstance.py:731} INFO - ::endgroup::
[2024-12-13T00:58:28.388+0000] {base.py:84} INFO - Retrieving connection 'ecobalyse_database_connection'
[2024-12-13T00:58:28.396+0000] {logging_mixin.py:190} INFO - 0    (0.14571477426236856, 24.225601759405862, 111....
1    (0.021157835040455618, 2.7420274483981206, 7.8...
2    (0.18125129163341008, 20.854181978411905, 91.0...
3    (0.3056645105082514, 32.17516972790083, 109.14...
4    (0.094096956587051, 12.514815452447031, 56.131...
5    (0.05703681788640483, 10.927431778205628, 55.2...
6    (0.05108461486029837, 9.390235390975775, 28.21...
7    (0.13183128895796983, 11.905082994041125, 49.8...
8    (0.04848777437231141, 8.150194061564463, 18.26...
9    (0.08516358919519475, 8.451976399240358, 26.62...
dtype: object
[2024-12-13T00:58:28.400+0000] {taskinstance.py:3311} ERROR - Task failed with exception
Traceback (most recent call last):
  File "/home/airflow/.local/lib/python3.12/site-packages/airflow/models/taskinstance.py", line 767, in _execute_task
    result = _execute_callable(context=context, **execute_callable_kwargs)
             ^^^^^^^^^^^^^^^^^^^^^^^^^^^^^^^^^^^^^^^^^^^^^^^^^^^^^^^^^^^^^
  File "/home/airflow/.local/lib/python3.12/site-packages/airflow/models/taskinstance.py", line 733, in _execute_callable
    return ExecutionCallableRunner(
           ^^^^^^^^^^^^^^^^^^^^^^^^
  File "/home/airflow/.local/lib/python3.12/site-packages/airflow/utils/operator_helpers.py", line 252, in run
    return self.func(*args, **kwargs)
           ^^^^^^^^^^^^^^^^^^^^^^^^^^
  File "/home/airflow/.local/lib/python3.12/site-packages/airflow/models/baseoperator.py", line 417, in wrapper
    return func(self, *args, **kwargs)
           ^^^^^^^^^^^^^^^^^^^^^^^^^^^
  File "/home/airflow/.local/lib/python3.12/site-packages/airflow/operators/python.py", line 238, in execute
    return_value = self.execute_callable()
                   ^^^^^^^^^^^^^^^^^^^^^^^
  File "/home/airflow/.local/lib/python3.12/site-packages/airflow/operators/python.py", line 256, in execute_callable
    return runner.run(*self.op_args, **self.op_kwargs)
           ^^^^^^^^^^^^^^^^^^^^^^^^^^^^^^^^^^^^^^^^^^^
  File "/home/airflow/.local/lib/python3.12/site-packages/airflow/utils/operator_helpers.py", line 252, in run
    return self.func(*args, **kwargs)
           ^^^^^^^^^^^^^^^^^^^^^^^^^^
  File "/opt/airflow/dags/data_transformations.py", line 156, in insert_data_into_postgres
    cursor.execute(insert_query,record)
psycopg2.ProgrammingError: can't adapt type 'dict'
[2024-12-13T00:58:28.412+0000] {logging_mixin.py:190} INFO - Task instance in failure state
[2024-12-13T00:58:28.412+0000] {logging_mixin.py:190} INFO - Task start:2024-12-13 00:58:27.999779+00:00 end:2024-12-13 00:58:28.411721+00:00 duration:0.411942
[2024-12-13T00:58:28.412+0000] {logging_mixin.py:190} INFO - Task:<Task(PythonOperator): Load_Data> dag:<DAG: ecobalyse_dag> dagrun:<DagRun ecobalyse_dag @ 2024-12-13 00:57:15.184756+00:00: manual__2024-12-13T00:57:15.184756+00:00, state:running, queued_at: 2024-12-13 00:57:15.195244+00:00. externally triggered: True>
[2024-12-13T00:58:28.412+0000] {logging_mixin.py:190} INFO - Failure caused by can't adapt type 'dict'
[2024-12-13T00:58:28.412+0000] {taskinstance.py:1225} INFO - Marking task as UP_FOR_RETRY. dag_id=ecobalyse_dag, task_id=Load_Data, run_id=manual__2024-12-13T00:57:15.184756+00:00, execution_date=20241213T005715, start_date=20241213T005827, end_date=20241213T005828
[2024-12-13T00:58:28.425+0000] {taskinstance.py:340} INFO - ::group::Post task execution logs
[2024-12-13T00:58:28.425+0000] {standard_task_runner.py:124} ERROR - Failed to execute job 271 for task Load_Data (can't adapt type 'dict'; 1735)
Traceback (most recent call last):
  File "/home/airflow/.local/lib/python3.12/site-packages/airflow/task/task_runner/standard_task_runner.py", line 117, in _start_by_fork
    ret = args.func(args, dag=self.dag)
          ^^^^^^^^^^^^^^^^^^^^^^^^^^^^^
  File "/home/airflow/.local/lib/python3.12/site-packages/airflow/cli/cli_config.py", line 49, in command
    return func(*args, **kwargs)
           ^^^^^^^^^^^^^^^^^^^^^
  File "/home/airflow/.local/lib/python3.12/site-packages/airflow/utils/cli.py", line 116, in wrapper
    return f(*args, **kwargs)
           ^^^^^^^^^^^^^^^^^^
  File "/home/airflow/.local/lib/python3.12/site-packages/airflow/cli/commands/task_command.py", line 483, in task_run
    task_return_code = _run_task_by_selected_method(args, _dag, ti)
                       ^^^^^^^^^^^^^^^^^^^^^^^^^^^^^^^^^^^^^^^^^^^^
  File "/home/airflow/.local/lib/python3.12/site-packages/airflow/cli/commands/task_command.py", line 256, in _run_task_by_selected_method
    return _run_raw_task(args, ti)
           ^^^^^^^^^^^^^^^^^^^^^^^
  File "/home/airflow/.local/lib/python3.12/site-packages/airflow/cli/commands/task_command.py", line 341, in _run_raw_task
    return ti._run_raw_task(
           ^^^^^^^^^^^^^^^^^
  File "/home/airflow/.local/lib/python3.12/site-packages/airflow/utils/session.py", line 97, in wrapper
    return func(*args, session=session, **kwargs)
           ^^^^^^^^^^^^^^^^^^^^^^^^^^^^^^^^^^^^^^
  File "/home/airflow/.local/lib/python3.12/site-packages/airflow/models/taskinstance.py", line 3005, in _run_raw_task
    return _run_raw_task(
           ^^^^^^^^^^^^^^
  File "/home/airflow/.local/lib/python3.12/site-packages/airflow/models/taskinstance.py", line 273, in _run_raw_task
    TaskInstance._execute_task_with_callbacks(
  File "/home/airflow/.local/lib/python3.12/site-packages/airflow/models/taskinstance.py", line 3159, in _execute_task_with_callbacks
    result = self._execute_task(context, task_orig)
             ^^^^^^^^^^^^^^^^^^^^^^^^^^^^^^^^^^^^^^
  File "/home/airflow/.local/lib/python3.12/site-packages/airflow/models/taskinstance.py", line 3183, in _execute_task
    return _execute_task(self, context, task_orig)
           ^^^^^^^^^^^^^^^^^^^^^^^^^^^^^^^^^^^^^^^
  File "/home/airflow/.local/lib/python3.12/site-packages/airflow/models/taskinstance.py", line 767, in _execute_task
    result = _execute_callable(context=context, **execute_callable_kwargs)
             ^^^^^^^^^^^^^^^^^^^^^^^^^^^^^^^^^^^^^^^^^^^^^^^^^^^^^^^^^^^^^
  File "/home/airflow/.local/lib/python3.12/site-packages/airflow/models/taskinstance.py", line 733, in _execute_callable
    return ExecutionCallableRunner(
           ^^^^^^^^^^^^^^^^^^^^^^^^
  File "/home/airflow/.local/lib/python3.12/site-packages/airflow/utils/operator_helpers.py", line 252, in run
    return self.func(*args, **kwargs)
           ^^^^^^^^^^^^^^^^^^^^^^^^^^
  File "/home/airflow/.local/lib/python3.12/site-packages/airflow/models/baseoperator.py", line 417, in wrapper
    return func(self, *args, **kwargs)
           ^^^^^^^^^^^^^^^^^^^^^^^^^^^
  File "/home/airflow/.local/lib/python3.12/site-packages/airflow/operators/python.py", line 238, in execute
    return_value = self.execute_callable()
                   ^^^^^^^^^^^^^^^^^^^^^^^
  File "/home/airflow/.local/lib/python3.12/site-packages/airflow/operators/python.py", line 256, in execute_callable
    return runner.run(*self.op_args, **self.op_kwargs)
           ^^^^^^^^^^^^^^^^^^^^^^^^^^^^^^^^^^^^^^^^^^^
  File "/home/airflow/.local/lib/python3.12/site-packages/airflow/utils/operator_helpers.py", line 252, in run
    return self.func(*args, **kwargs)
           ^^^^^^^^^^^^^^^^^^^^^^^^^^
  File "/opt/airflow/dags/data_transformations.py", line 156, in insert_data_into_postgres
    cursor.execute(insert_query,record)
psycopg2.ProgrammingError: can't adapt type 'dict'
[2024-12-13T00:58:28.445+0000] {local_task_job_runner.py:266} INFO - Task exited with return code 1
[2024-12-13T00:58:28.466+0000] {taskinstance.py:3895} INFO - 0 downstream tasks scheduled from follow-on schedule check
[2024-12-13T00:58:28.467+0000] {local_task_job_runner.py:245} INFO - ::endgroup::
