[2024-12-14T14:11:24.976+0000] {local_task_job_runner.py:123} INFO - ::group::Pre task execution logs
[2024-12-14T14:11:24.999+0000] {taskinstance.py:2613} INFO - Dependencies all met for dep_context=non-requeueable deps ti=<TaskInstance: ecobalyse_dag.best_Model manual__2024-12-14T14:10:01.550271+00:00 [queued]>
[2024-12-14T14:11:25.008+0000] {taskinstance.py:2613} INFO - Dependencies all met for dep_context=requeueable deps ti=<TaskInstance: ecobalyse_dag.best_Model manual__2024-12-14T14:10:01.550271+00:00 [queued]>
[2024-12-14T14:11:25.008+0000] {taskinstance.py:2866} INFO - Starting attempt 2 of 3
[2024-12-14T14:11:25.017+0000] {taskinstance.py:2889} INFO - Executing <Task(PythonOperator): best_Model> on 2024-12-14 14:10:01.550271+00:00
[2024-12-14T14:11:25.024+0000] {warnings.py:112} WARNING - /home/***/.local/lib/python3.12/site-packages/***/task/task_runner/standard_task_runner.py:70: DeprecationWarning: This process (pid=11970) is multi-threaded, use of fork() may lead to deadlocks in the child.
  pid = os.fork()

[2024-12-14T14:11:25.025+0000] {standard_task_runner.py:72} INFO - Started process 11993 to run task
[2024-12-14T14:11:25.027+0000] {standard_task_runner.py:104} INFO - Running: ['***', 'tasks', 'run', 'ecobalyse_dag', 'best_Model', 'manual__2024-12-14T14:10:01.550271+00:00', '--job-id', '820', '--raw', '--subdir', 'DAGS_FOLDER/data_transformations.py', '--cfg-path', '/tmp/tmp5f8s0_4j']
[2024-12-14T14:11:25.028+0000] {standard_task_runner.py:105} INFO - Job 820: Subtask best_Model
[2024-12-14T14:11:25.070+0000] {task_command.py:467} INFO - Running <TaskInstance: ecobalyse_dag.best_Model manual__2024-12-14T14:10:01.550271+00:00 [running]> on host a07fab1983be
[2024-12-14T14:11:25.165+0000] {taskinstance.py:3132} INFO - Exporting env vars: AIRFLOW_CTX_DAG_EMAIL='thiernosidybah232@gmail.com' AIRFLOW_CTX_DAG_OWNER='***' AIRFLOW_CTX_DAG_ID='ecobalyse_dag' AIRFLOW_CTX_TASK_ID='best_Model' AIRFLOW_CTX_EXECUTION_DATE='2024-12-14T14:10:01.550271+00:00' AIRFLOW_CTX_TRY_NUMBER='2' AIRFLOW_CTX_DAG_RUN_ID='manual__2024-12-14T14:10:01.550271+00:00'
[2024-12-14T14:11:25.166+0000] {logging_mixin.py:190} INFO - Task instance is in running state
[2024-12-14T14:11:25.167+0000] {logging_mixin.py:190} INFO -  Previous state of the Task instance: queued
[2024-12-14T14:11:25.167+0000] {logging_mixin.py:190} INFO - Current task name:best_Model state:running start_date:2024-12-14 14:11:24.999591+00:00
[2024-12-14T14:11:25.167+0000] {logging_mixin.py:190} INFO - Dag name:ecobalyse_dag and current dag run status:running
[2024-12-14T14:11:25.168+0000] {taskinstance.py:731} INFO - ::endgroup::
[2024-12-14T14:11:25.175+0000] {taskinstance.py:3311} ERROR - Task failed with exception
Traceback (most recent call last):
  File "/home/airflow/.local/lib/python3.12/site-packages/pandas/core/indexes/base.py", line 3791, in get_loc
    return self._engine.get_loc(casted_key)
           ^^^^^^^^^^^^^^^^^^^^^^^^^^^^^^^^
  File "index.pyx", line 152, in pandas._libs.index.IndexEngine.get_loc
  File "index.pyx", line 181, in pandas._libs.index.IndexEngine.get_loc
  File "pandas/_libs/hashtable_class_helper.pxi", line 7080, in pandas._libs.hashtable.PyObjectHashTable.get_item
  File "pandas/_libs/hashtable_class_helper.pxi", line 7088, in pandas._libs.hashtable.PyObjectHashTable.get_item
KeyError: 'rmse_test'

The above exception was the direct cause of the following exception:

Traceback (most recent call last):
  File "/home/airflow/.local/lib/python3.12/site-packages/airflow/models/taskinstance.py", line 767, in _execute_task
    result = _execute_callable(context=context, **execute_callable_kwargs)
             ^^^^^^^^^^^^^^^^^^^^^^^^^^^^^^^^^^^^^^^^^^^^^^^^^^^^^^^^^^^^^
  File "/home/airflow/.local/lib/python3.12/site-packages/airflow/models/taskinstance.py", line 733, in _execute_callable
    return ExecutionCallableRunner(
           ^^^^^^^^^^^^^^^^^^^^^^^^
  File "/home/airflow/.local/lib/python3.12/site-packages/airflow/utils/operator_helpers.py", line 252, in run
    return self.func(*args, **kwargs)
           ^^^^^^^^^^^^^^^^^^^^^^^^^^
  File "/home/airflow/.local/lib/python3.12/site-packages/airflow/models/baseoperator.py", line 417, in wrapper
    return func(self, *args, **kwargs)
           ^^^^^^^^^^^^^^^^^^^^^^^^^^^
  File "/home/airflow/.local/lib/python3.12/site-packages/airflow/operators/python.py", line 238, in execute
    return_value = self.execute_callable()
                   ^^^^^^^^^^^^^^^^^^^^^^^
  File "/home/airflow/.local/lib/python3.12/site-packages/airflow/operators/python.py", line 256, in execute_callable
    return runner.run(*self.op_args, **self.op_kwargs)
           ^^^^^^^^^^^^^^^^^^^^^^^^^^^^^^^^^^^^^^^^^^^
  File "/home/airflow/.local/lib/python3.12/site-packages/airflow/utils/operator_helpers.py", line 252, in run
    return self.func(*args, **kwargs)
           ^^^^^^^^^^^^^^^^^^^^^^^^^^
  File "/opt/airflow/dags/data_transformations.py", line 501, in choose_the_best_model
    rmse_model[model]= data["rmse_test"]
                       ~~~~^^^^^^^^^^^^^
  File "/home/airflow/.local/lib/python3.12/site-packages/pandas/core/frame.py", line 3893, in __getitem__
    indexer = self.columns.get_loc(key)
              ^^^^^^^^^^^^^^^^^^^^^^^^^
  File "/home/airflow/.local/lib/python3.12/site-packages/pandas/core/indexes/base.py", line 3798, in get_loc
    raise KeyError(key) from err
KeyError: 'rmse_test'
[2024-12-14T14:11:25.197+0000] {logging_mixin.py:190} INFO - Task instance in failure state
[2024-12-14T14:11:25.197+0000] {logging_mixin.py:190} INFO - Task start:2024-12-14 14:11:24.999591+00:00 end:2024-12-14 14:11:25.196683+00:00 duration:0.197092
[2024-12-14T14:11:25.197+0000] {logging_mixin.py:190} INFO - Task:<Task(PythonOperator): best_Model> dag:<DAG: ecobalyse_dag> dagrun:<DagRun ecobalyse_dag @ 2024-12-14 14:10:01.550271+00:00: manual__2024-12-14T14:10:01.550271+00:00, state:running, queued_at: 2024-12-14 14:10:01.567313+00:00. externally triggered: True>
[2024-12-14T14:11:25.198+0000] {logging_mixin.py:190} INFO - Failure caused by 'rmse_test'
[2024-12-14T14:11:25.198+0000] {taskinstance.py:1225} INFO - Marking task as UP_FOR_RETRY. dag_id=ecobalyse_dag, task_id=best_Model, run_id=manual__2024-12-14T14:10:01.550271+00:00, execution_date=20241214T141001, start_date=20241214T141124, end_date=20241214T141125
[2024-12-14T14:11:25.211+0000] {taskinstance.py:340} INFO - ::group::Post task execution logs
[2024-12-14T14:11:25.211+0000] {standard_task_runner.py:124} ERROR - Failed to execute job 820 for task best_Model ('rmse_test'; 11993)
Traceback (most recent call last):
  File "/home/airflow/.local/lib/python3.12/site-packages/pandas/core/indexes/base.py", line 3791, in get_loc
    return self._engine.get_loc(casted_key)
           ^^^^^^^^^^^^^^^^^^^^^^^^^^^^^^^^
  File "index.pyx", line 152, in pandas._libs.index.IndexEngine.get_loc
  File "index.pyx", line 181, in pandas._libs.index.IndexEngine.get_loc
  File "pandas/_libs/hashtable_class_helper.pxi", line 7080, in pandas._libs.hashtable.PyObjectHashTable.get_item
  File "pandas/_libs/hashtable_class_helper.pxi", line 7088, in pandas._libs.hashtable.PyObjectHashTable.get_item
KeyError: 'rmse_test'

The above exception was the direct cause of the following exception:

Traceback (most recent call last):
  File "/home/airflow/.local/lib/python3.12/site-packages/airflow/task/task_runner/standard_task_runner.py", line 117, in _start_by_fork
    ret = args.func(args, dag=self.dag)
          ^^^^^^^^^^^^^^^^^^^^^^^^^^^^^
  File "/home/airflow/.local/lib/python3.12/site-packages/airflow/cli/cli_config.py", line 49, in command
    return func(*args, **kwargs)
           ^^^^^^^^^^^^^^^^^^^^^
  File "/home/airflow/.local/lib/python3.12/site-packages/airflow/utils/cli.py", line 116, in wrapper
    return f(*args, **kwargs)
           ^^^^^^^^^^^^^^^^^^
  File "/home/airflow/.local/lib/python3.12/site-packages/airflow/cli/commands/task_command.py", line 483, in task_run
    task_return_code = _run_task_by_selected_method(args, _dag, ti)
                       ^^^^^^^^^^^^^^^^^^^^^^^^^^^^^^^^^^^^^^^^^^^^
  File "/home/airflow/.local/lib/python3.12/site-packages/airflow/cli/commands/task_command.py", line 256, in _run_task_by_selected_method
    return _run_raw_task(args, ti)
           ^^^^^^^^^^^^^^^^^^^^^^^
  File "/home/airflow/.local/lib/python3.12/site-packages/airflow/cli/commands/task_command.py", line 341, in _run_raw_task
    return ti._run_raw_task(
           ^^^^^^^^^^^^^^^^^
  File "/home/airflow/.local/lib/python3.12/site-packages/airflow/utils/session.py", line 97, in wrapper
    return func(*args, session=session, **kwargs)
           ^^^^^^^^^^^^^^^^^^^^^^^^^^^^^^^^^^^^^^
  File "/home/airflow/.local/lib/python3.12/site-packages/airflow/models/taskinstance.py", line 3005, in _run_raw_task
    return _run_raw_task(
           ^^^^^^^^^^^^^^
  File "/home/airflow/.local/lib/python3.12/site-packages/airflow/models/taskinstance.py", line 273, in _run_raw_task
    TaskInstance._execute_task_with_callbacks(
  File "/home/airflow/.local/lib/python3.12/site-packages/airflow/models/taskinstance.py", line 3159, in _execute_task_with_callbacks
    result = self._execute_task(context, task_orig)
             ^^^^^^^^^^^^^^^^^^^^^^^^^^^^^^^^^^^^^^
  File "/home/airflow/.local/lib/python3.12/site-packages/airflow/models/taskinstance.py", line 3183, in _execute_task
    return _execute_task(self, context, task_orig)
           ^^^^^^^^^^^^^^^^^^^^^^^^^^^^^^^^^^^^^^^
  File "/home/airflow/.local/lib/python3.12/site-packages/airflow/models/taskinstance.py", line 767, in _execute_task
    result = _execute_callable(context=context, **execute_callable_kwargs)
             ^^^^^^^^^^^^^^^^^^^^^^^^^^^^^^^^^^^^^^^^^^^^^^^^^^^^^^^^^^^^^
  File "/home/airflow/.local/lib/python3.12/site-packages/airflow/models/taskinstance.py", line 733, in _execute_callable
    return ExecutionCallableRunner(
           ^^^^^^^^^^^^^^^^^^^^^^^^
  File "/home/airflow/.local/lib/python3.12/site-packages/airflow/utils/operator_helpers.py", line 252, in run
    return self.func(*args, **kwargs)
           ^^^^^^^^^^^^^^^^^^^^^^^^^^
  File "/home/airflow/.local/lib/python3.12/site-packages/airflow/models/baseoperator.py", line 417, in wrapper
    return func(self, *args, **kwargs)
           ^^^^^^^^^^^^^^^^^^^^^^^^^^^
  File "/home/airflow/.local/lib/python3.12/site-packages/airflow/operators/python.py", line 238, in execute
    return_value = self.execute_callable()
                   ^^^^^^^^^^^^^^^^^^^^^^^
  File "/home/airflow/.local/lib/python3.12/site-packages/airflow/operators/python.py", line 256, in execute_callable
    return runner.run(*self.op_args, **self.op_kwargs)
           ^^^^^^^^^^^^^^^^^^^^^^^^^^^^^^^^^^^^^^^^^^^
  File "/home/airflow/.local/lib/python3.12/site-packages/airflow/utils/operator_helpers.py", line 252, in run
    return self.func(*args, **kwargs)
           ^^^^^^^^^^^^^^^^^^^^^^^^^^
  File "/opt/airflow/dags/data_transformations.py", line 501, in choose_the_best_model
    rmse_model[model]= data["rmse_test"]
                       ~~~~^^^^^^^^^^^^^
  File "/home/airflow/.local/lib/python3.12/site-packages/pandas/core/frame.py", line 3893, in __getitem__
    indexer = self.columns.get_loc(key)
              ^^^^^^^^^^^^^^^^^^^^^^^^^
  File "/home/airflow/.local/lib/python3.12/site-packages/pandas/core/indexes/base.py", line 3798, in get_loc
    raise KeyError(key) from err
KeyError: 'rmse_test'
[2024-12-14T14:11:25.238+0000] {local_task_job_runner.py:266} INFO - Task exited with return code 1
[2024-12-14T14:11:25.260+0000] {taskinstance.py:3895} INFO - 0 downstream tasks scheduled from follow-on schedule check
[2024-12-14T14:11:25.261+0000] {local_task_job_runner.py:245} INFO - ::endgroup::
