[2024-12-14T07:22:16.386+0000] {local_task_job_runner.py:123} INFO - ::group::Pre task execution logs
[2024-12-14T07:22:16.399+0000] {taskinstance.py:2613} INFO - Dependencies all met for dep_context=non-requeueable deps ti=<TaskInstance: ecobalyse_dag.create_table scheduled__2024-12-13T00:00:00+00:00 [queued]>
[2024-12-14T07:22:16.405+0000] {taskinstance.py:2613} INFO - Dependencies all met for dep_context=requeueable deps ti=<TaskInstance: ecobalyse_dag.create_table scheduled__2024-12-13T00:00:00+00:00 [queued]>
[2024-12-14T07:22:16.405+0000] {taskinstance.py:2866} INFO - Starting attempt 2 of 3
[2024-12-14T07:22:16.416+0000] {taskinstance.py:2889} INFO - Executing <Task(PostgresOperator): create_table> on 2024-12-13 00:00:00+00:00
[2024-12-14T07:22:16.421+0000] {warnings.py:112} WARNING - /home/***/.local/lib/python3.12/site-packages/***/task/task_runner/standard_task_runner.py:70: DeprecationWarning: This process (pid=98) is multi-threaded, use of fork() may lead to deadlocks in the child.
  pid = os.fork()

[2024-12-14T07:22:16.422+0000] {standard_task_runner.py:72} INFO - Started process 107 to run task
[2024-12-14T07:22:16.423+0000] {standard_task_runner.py:104} INFO - Running: ['***', 'tasks', 'run', 'ecobalyse_dag', 'create_table', 'scheduled__2024-12-13T00:00:00+00:00', '--job-id', '434', '--raw', '--subdir', 'DAGS_FOLDER/data_transformations.py', '--cfg-path', '/tmp/tmp4871nigd']
[2024-12-14T07:22:16.424+0000] {standard_task_runner.py:105} INFO - Job 434: Subtask create_table
[2024-12-14T07:22:16.452+0000] {task_command.py:467} INFO - Running <TaskInstance: ecobalyse_dag.create_table scheduled__2024-12-13T00:00:00+00:00 [running]> on host 474fcd006df3
[2024-12-14T07:22:16.650+0000] {taskinstance.py:3132} INFO - Exporting env vars: AIRFLOW_CTX_DAG_EMAIL='thiernosidybah232@gmail.com' AIRFLOW_CTX_DAG_OWNER='***' AIRFLOW_CTX_DAG_ID='ecobalyse_dag' AIRFLOW_CTX_TASK_ID='create_table' AIRFLOW_CTX_EXECUTION_DATE='2024-12-13T00:00:00+00:00' AIRFLOW_CTX_TRY_NUMBER='2' AIRFLOW_CTX_DAG_RUN_ID='scheduled__2024-12-13T00:00:00+00:00'
[2024-12-14T07:22:16.651+0000] {logging_mixin.py:190} INFO - Task instance is in running state
[2024-12-14T07:22:16.651+0000] {logging_mixin.py:190} INFO -  Previous state of the Task instance: queued
[2024-12-14T07:22:16.651+0000] {logging_mixin.py:190} INFO - Current task name:create_table state:running start_date:2024-12-14 07:22:16.399261+00:00
[2024-12-14T07:22:16.652+0000] {logging_mixin.py:190} INFO - Dag name:ecobalyse_dag and current dag run status:running
[2024-12-14T07:22:16.652+0000] {taskinstance.py:731} INFO - ::endgroup::
[2024-12-14T07:22:16.652+0000] {sql.py:278} INFO - Executing:  
                        DROP TABLE  IF EXISTS Ecobalyse_table;
                        CREATE TABLE IF NOT EXISTS Ecobalyse_table(
                           
                                acd NUMERIC,
                                cch NUMERIC,
                                etf NUMERIC, 
                                etf_c NUMERIC, 
                                fru NUMERIC, 
                                fwe NUMERIC,
                                htc NUMERIC,
                                htc_c NUMERIC, 
                                htn NUMERIC,
                                htn_c NUMERIC,
                                ior NUMERIC,  
                                ldu NUMERIC, 
                                mru NUMERIC, 
                                ozd NUMERIC,
                                pco NUMERIC, 
                                pma NUMERIC,
                                swe NUMERIC,
                                tre NUMERIC,
                                wtu NUMERIC,
                                ecs NUMERIC, 
                                pef NUMERIC, 
                                air_transport_ratio NUMERIC, 
                                business TEXT,
                                country_dyeing TEXT,
                                country_fabric TEXT,
                                country_making TEXT, 
                                country_spinning TEXT, 
                                fabric_process TEXT,
                                making_complexity TEXT, 
                                making_dead_stock NUMERIC,
                                making_waste NUMERIC, 
                                mass NUMERIC,
                                number_of_references NUMERIC,
                                physical_durability NUMERIC,
                                price NUMERIC, 
                                product TEXT,
                                surface_mass NUMERIC, 
                                traceability BOOLEAN,
                                upcycled BOOLEAN,
                                yarn_size NUMERIC
                           
                           
                           
                           
                           ); 
                    
[2024-12-14T07:22:16.660+0000] {base.py:84} INFO - Retrieving connection 'ecobalyse_database_connection'
[2024-12-14T07:22:16.666+0000] {base.py:84} INFO - Retrieving connection 'ecobalyse_database_connection'
[2024-12-14T07:22:16.666+0000] {taskinstance.py:3311} ERROR - Task failed with exception
Traceback (most recent call last):
  File "/home/airflow/.local/lib/python3.12/site-packages/airflow/models/taskinstance.py", line 767, in _execute_task
    result = _execute_callable(context=context, **execute_callable_kwargs)
             ^^^^^^^^^^^^^^^^^^^^^^^^^^^^^^^^^^^^^^^^^^^^^^^^^^^^^^^^^^^^^
  File "/home/airflow/.local/lib/python3.12/site-packages/airflow/models/taskinstance.py", line 733, in _execute_callable
    return ExecutionCallableRunner(
           ^^^^^^^^^^^^^^^^^^^^^^^^
  File "/home/airflow/.local/lib/python3.12/site-packages/airflow/utils/operator_helpers.py", line 252, in run
    return self.func(*args, **kwargs)
           ^^^^^^^^^^^^^^^^^^^^^^^^^^
  File "/home/airflow/.local/lib/python3.12/site-packages/airflow/models/baseoperator.py", line 417, in wrapper
    return func(self, *args, **kwargs)
           ^^^^^^^^^^^^^^^^^^^^^^^^^^^
  File "/home/airflow/.local/lib/python3.12/site-packages/airflow/providers/common/sql/operators/sql.py", line 284, in execute
    output = hook.run(
             ^^^^^^^^^
  File "/home/airflow/.local/lib/python3.12/site-packages/airflow/providers/common/sql/hooks/sql.py", line 485, in run
    with self._create_autocommit_connection(autocommit) as conn:
         ^^^^^^^^^^^^^^^^^^^^^^^^^^^^^^^^^^^^^^^^^^^^^^
  File "/usr/local/lib/python3.12/contextlib.py", line 137, in __enter__
    return next(self.gen)
           ^^^^^^^^^^^^^^
  File "/home/airflow/.local/lib/python3.12/site-packages/airflow/providers/common/sql/hooks/sql.py", line 609, in _create_autocommit_connection
    with closing(self.get_conn()) as conn:
                 ^^^^^^^^^^^^^^^
  File "/home/airflow/.local/lib/python3.12/site-packages/airflow/providers/postgres/hooks/postgres.py", line 181, in get_conn
    self.conn = psycopg2.connect(**conn_args)
                ^^^^^^^^^^^^^^^^^^^^^^^^^^^^^
  File "/home/airflow/.local/lib/python3.12/site-packages/psycopg2/__init__.py", line 122, in connect
    conn = _connect(dsn, connection_factory=connection_factory, **kwasync)
           ^^^^^^^^^^^^^^^^^^^^^^^^^^^^^^^^^^^^^^^^^^^^^^^^^^^^^^^^^^^^^^^
psycopg2.OperationalError: connection to server at "172.24.0.2", port 5432 failed: Connection refused
	Is the server running on that host and accepting TCP/IP connections?

[2024-12-14T07:22:16.675+0000] {logging_mixin.py:190} INFO - Task instance in failure state
[2024-12-14T07:22:16.676+0000] {logging_mixin.py:190} INFO - Task start:2024-12-14 07:22:16.399261+00:00 end:2024-12-14 07:22:16.675401+00:00 duration:0.27614
[2024-12-14T07:22:16.676+0000] {logging_mixin.py:190} INFO - Task:<Task(PostgresOperator): create_table> dag:<DAG: ecobalyse_dag> dagrun:<DagRun ecobalyse_dag @ 2024-12-13 00:00:00+00:00: scheduled__2024-12-13T00:00:00+00:00, state:running, queued_at: 2024-12-14 07:21:05.753756+00:00. externally triggered: False>
[2024-12-14T07:22:16.676+0000] {logging_mixin.py:190} INFO - Failure caused by connection to server at "172.24.0.2", port 5432 failed: Connection refused
	Is the server running on that host and accepting TCP/IP connections?
[2024-12-14T07:22:16.677+0000] {taskinstance.py:1225} INFO - Marking task as UP_FOR_RETRY. dag_id=ecobalyse_dag, task_id=create_table, run_id=scheduled__2024-12-13T00:00:00+00:00, execution_date=20241213T000000, start_date=20241214T072216, end_date=20241214T072216
[2024-12-14T07:22:16.689+0000] {taskinstance.py:340} INFO - ::group::Post task execution logs
[2024-12-14T07:22:16.690+0000] {standard_task_runner.py:124} ERROR - Failed to execute job 434 for task create_table (connection to server at "172.24.0.2", port 5432 failed: Connection refused
	Is the server running on that host and accepting TCP/IP connections?
; 107)
Traceback (most recent call last):
  File "/home/airflow/.local/lib/python3.12/site-packages/airflow/task/task_runner/standard_task_runner.py", line 117, in _start_by_fork
    ret = args.func(args, dag=self.dag)
          ^^^^^^^^^^^^^^^^^^^^^^^^^^^^^
  File "/home/airflow/.local/lib/python3.12/site-packages/airflow/cli/cli_config.py", line 49, in command
    return func(*args, **kwargs)
           ^^^^^^^^^^^^^^^^^^^^^
  File "/home/airflow/.local/lib/python3.12/site-packages/airflow/utils/cli.py", line 116, in wrapper
    return f(*args, **kwargs)
           ^^^^^^^^^^^^^^^^^^
  File "/home/airflow/.local/lib/python3.12/site-packages/airflow/cli/commands/task_command.py", line 483, in task_run
    task_return_code = _run_task_by_selected_method(args, _dag, ti)
                       ^^^^^^^^^^^^^^^^^^^^^^^^^^^^^^^^^^^^^^^^^^^^
  File "/home/airflow/.local/lib/python3.12/site-packages/airflow/cli/commands/task_command.py", line 256, in _run_task_by_selected_method
    return _run_raw_task(args, ti)
           ^^^^^^^^^^^^^^^^^^^^^^^
  File "/home/airflow/.local/lib/python3.12/site-packages/airflow/cli/commands/task_command.py", line 341, in _run_raw_task
    return ti._run_raw_task(
           ^^^^^^^^^^^^^^^^^
  File "/home/airflow/.local/lib/python3.12/site-packages/airflow/utils/session.py", line 97, in wrapper
    return func(*args, session=session, **kwargs)
           ^^^^^^^^^^^^^^^^^^^^^^^^^^^^^^^^^^^^^^
  File "/home/airflow/.local/lib/python3.12/site-packages/airflow/models/taskinstance.py", line 3005, in _run_raw_task
    return _run_raw_task(
           ^^^^^^^^^^^^^^
  File "/home/airflow/.local/lib/python3.12/site-packages/airflow/models/taskinstance.py", line 273, in _run_raw_task
    TaskInstance._execute_task_with_callbacks(
  File "/home/airflow/.local/lib/python3.12/site-packages/airflow/models/taskinstance.py", line 3159, in _execute_task_with_callbacks
    result = self._execute_task(context, task_orig)
             ^^^^^^^^^^^^^^^^^^^^^^^^^^^^^^^^^^^^^^
  File "/home/airflow/.local/lib/python3.12/site-packages/airflow/models/taskinstance.py", line 3183, in _execute_task
    return _execute_task(self, context, task_orig)
           ^^^^^^^^^^^^^^^^^^^^^^^^^^^^^^^^^^^^^^^
  File "/home/airflow/.local/lib/python3.12/site-packages/airflow/models/taskinstance.py", line 767, in _execute_task
    result = _execute_callable(context=context, **execute_callable_kwargs)
             ^^^^^^^^^^^^^^^^^^^^^^^^^^^^^^^^^^^^^^^^^^^^^^^^^^^^^^^^^^^^^
  File "/home/airflow/.local/lib/python3.12/site-packages/airflow/models/taskinstance.py", line 733, in _execute_callable
    return ExecutionCallableRunner(
           ^^^^^^^^^^^^^^^^^^^^^^^^
  File "/home/airflow/.local/lib/python3.12/site-packages/airflow/utils/operator_helpers.py", line 252, in run
    return self.func(*args, **kwargs)
           ^^^^^^^^^^^^^^^^^^^^^^^^^^
  File "/home/airflow/.local/lib/python3.12/site-packages/airflow/models/baseoperator.py", line 417, in wrapper
    return func(self, *args, **kwargs)
           ^^^^^^^^^^^^^^^^^^^^^^^^^^^
  File "/home/airflow/.local/lib/python3.12/site-packages/airflow/providers/common/sql/operators/sql.py", line 284, in execute
    output = hook.run(
             ^^^^^^^^^
  File "/home/airflow/.local/lib/python3.12/site-packages/airflow/providers/common/sql/hooks/sql.py", line 485, in run
    with self._create_autocommit_connection(autocommit) as conn:
         ^^^^^^^^^^^^^^^^^^^^^^^^^^^^^^^^^^^^^^^^^^^^^^
  File "/usr/local/lib/python3.12/contextlib.py", line 137, in __enter__
    return next(self.gen)
           ^^^^^^^^^^^^^^
  File "/home/airflow/.local/lib/python3.12/site-packages/airflow/providers/common/sql/hooks/sql.py", line 609, in _create_autocommit_connection
    with closing(self.get_conn()) as conn:
                 ^^^^^^^^^^^^^^^
  File "/home/airflow/.local/lib/python3.12/site-packages/airflow/providers/postgres/hooks/postgres.py", line 181, in get_conn
    self.conn = psycopg2.connect(**conn_args)
                ^^^^^^^^^^^^^^^^^^^^^^^^^^^^^
  File "/home/airflow/.local/lib/python3.12/site-packages/psycopg2/__init__.py", line 122, in connect
    conn = _connect(dsn, connection_factory=connection_factory, **kwasync)
           ^^^^^^^^^^^^^^^^^^^^^^^^^^^^^^^^^^^^^^^^^^^^^^^^^^^^^^^^^^^^^^^
psycopg2.OperationalError: connection to server at "172.24.0.2", port 5432 failed: Connection refused
	Is the server running on that host and accepting TCP/IP connections?

[2024-12-14T07:22:16.716+0000] {local_task_job_runner.py:266} INFO - Task exited with return code 1
[2024-12-14T07:22:16.729+0000] {taskinstance.py:3895} INFO - 0 downstream tasks scheduled from follow-on schedule check
[2024-12-14T07:22:16.730+0000] {local_task_job_runner.py:245} INFO - ::endgroup::
